Workbook

Sheet Read Me
A1: Elite RT Value Calculator
A2: Companion to the Elite Respiratory Therapy Service Line deck · Respiratory Gate Egypt · Discussion draft, October 2026
A4: Purpose | B4: Turns Elite's own operational and financial data into revenue and cost-avoidance scenarios for the respiratory service line.
A5: Status | B5: NO ELITE DATA ENTERED YET. Savings show 'Baseline required' until inputs are filled. No values are invented.
A6: How to use | B6: 1) Fill every yellow cell on 'Inputs' (and the yellow cells on 'Revenue'). 2) Pick scenarios with the selectors on 'Value Bridge'. 3) Review 'Savings Scenarios' and 'Value Bridge'.
A7: Legend · yellow fill | B7: Elite input — enter hospital data here.
A8: Legend · blue text | B8: Assumption or scenario lever set by Respiratory Gate (editable).
A9: Legend · black text | B9: Formula — do not overwrite.
A10: Legend · green text | B10: Link to another sheet.
A11: Rule 1 | B11: Gross revenue is not profit. Contribution margin requires Elite cost data.
A12: Rule 2 | B12: Package price (EGP 800–1,200 per occupied ICU respiratory patient-day) is a commercial assumption, subject to Elite Finance, payer and contract validation; not an established Egyptian reimbursement rate.
A13: Rule 3 | B13: Savings percentages (5% / 10% / 15%) are sensitivities applied to Elite's baseline, not forecasts or claims.
A14: Rule 4 | B14: Ventilator, NIV/HFNC and consumable levers can overlap (circuits, filters, interfaces). Finance should de-duplicate before quoting a total.
A15: Rule 5 | B15: Recovered billing (unbilled eligible activity × tariff × collection rate) is counted as revenue on the Value Bridge, not as a saving.
A16: Source | B16: ICU beds = 50: Elite Hospital official website, Intensive Care service page (elitehospital.org, accessed 6 Oct 2026).

Sheet Inputs
A1: Elite hospital inputs
A2: Yellow = Elite data required. All figures annual unless stated. Leave blank if unknown — formulas will show 'Baseline required'.
A4: Variable | B4: Unit | C4: Value | D4: Data owner | E4: Format / note
A5: ICU ACTIVITY
A6: ICU beds | B6: beds | C6: 50 | D6: Verified | E6: Elite official ICU page (elitehospital.org, 6 Oct 2026)
A7: ICU occupancy rate | B7: % | D7: ICU / Admissions | E7: Annual average, as a percentage (e.g. enter 0.8 for 80%)
A8: Ventilated patient-days | B8: patient-days / yr | D8: ICU | E8: Invasive mechanical ventilation days, all ICUs
A9: Average ventilator days per patient | B9: days | D9: ICU | E9: Mean duration of invasive ventilation
A10: NIV patient-days | B10: patient-days / yr | D10: ICU | E10: NIV / CPAP / BiPAP days
A11: HFNC patient-days | B11: patient-days / yr | D11: ICU | E11: High-flow nasal cannula days
A12: Oxygen consumption | B12: m³ or units / yr | D12: Supply chain | E12: As purchased (state unit in note)
A13: UNIT COSTS
A14: Cost per ventilator-day | B14: EGP | D14: Finance | E14: Consumables + device + direct resources per ventilated day
A15: Cost per NIV day | B15: EGP | D15: Finance | E15: Interfaces, circuits, device cost per NIV day
A16: Cost per HFNC day | B16: EGP | D16: Finance | E16: Circuits, humidification, device cost per HFNC day
A17: SPEND (EGP / YEAR)
A18: Oxygen spend | B18: EGP / yr | D18: Finance | E18: Total medical oxygen purchasing
A19: Respiratory consumable expenditure | B19: EGP / yr | D19: Finance | E19: Circuits, HME/HMEF, filters, closed suction, nebulizer kits, interfaces, HFNC circuits, humidification
A20: Respiratory equipment rental | B20: EGP / yr | D20: Biomedical | E20: If applicable
A21: Respiratory equipment maintenance | B21: EGP / yr | D21: Biomedical | E21: Service contracts and repairs
A22: Planned respiratory equipment purchases | B22: EGP / yr | D22: Biomedical | E22: Capital budget for ventilators, NIV, HFNC, humidifiers, transport ventilators
A23: Current respiratory staffing expenditure | B23: EGP / yr | D23: HR / Finance | E23: Staff currently delivering respiratory tasks
A24: Overtime expenditure (respiratory-related) | B24: EGP / yr | D24: HR / Finance
A25: PFT outsourcing | B25: EGP / yr | D25: Finance | E25: If applicable
A26: External respiratory service expenditure | B26: EGP / yr | D26: Finance | E26: If applicable
A27: USAGE (UNITS / YEAR)
A28: Ventilator circuit usage | B28: units / yr | D28: Supply chain
A29: Filter usage | B29: units / yr | D29: Supply chain
A30: Closed suction usage | B30: units / yr | D30: Supply chain
A31: HFNC circuit usage | B31: units / yr | D31: Supply chain
A32: NIV interface usage | B32: units / yr | D32: Supply chain
A33: Respiratory equipment inventory | B33: devices | D33: Biomedical | E33: Ventilators, NIV, HFNC, humidifiers, nebulizers, transport ventilators
A34: Respiratory equipment utilization rate | B34: % | D34: Biomedical | E34: Average in-use time ÷ available time
A35: BILLING
A36: Current billable respiratory activities | B36: activities / yr | D36: Finance / Billing | E36: Activities billed today
A37: Unbilled eligible respiratory activities | B37: activities / yr | D37: Finance / Billing | E37: Performed but not captured (from audit)
A38: Average tariff per respiratory activity | B38: EGP | D38: Finance / Billing
A39: Actual collection rate | B39: % | D39: Finance | E39: Collected ÷ billed

Sheet Savings Scenarios
A1: Cost-avoidance scenarios (EGP / year)
A2: Annual saving = Elite baseline × scenario %. Percentages are sensitivities, not forecasts. 'Baseline required' until the Inputs are filled.
A4: Scenario % | D4: Low | E4: Mid | F4: High
A5: Applied to each lever's baseline (editable) | D5: 0.05 | E5: 0.1 | F5: 0.15
A7: Cost-avoidance lever | B7: Baseline formula | C7: Baseline (EGP / yr) | D7: Low | E7: Mid | F7: High
A8: Ventilator resources | B8: Ventilated patient-days × cost per ventilator-day | C8: =IF(OR(Inputs!$C$8="",Inputs!$C$14=""),"",Inputs!$C$8*Inputs!$C$14) | D8: =IF(C8="","Baseline required",C8*D$5) -> Baseline required | E8: =IF(C8="","Baseline required",C8*E$5) -> Baseline required | F8: =IF(C8="","Baseline required",C8*F$5) -> Baseline required
A9: NIV / HFNC utilization | B9: NIV days × cost per NIV day + HFNC days × cost per HFNC day | C9: =IF(AND(OR(Inputs!$C$10="",Inputs!$C$15=""),OR(Inputs!$C$11="",Inputs!$C$16="")),"",N(Inputs!$C$10)*N(Inputs!$C$15)+N(Inputs!$C$11)*N(Inputs!$C$16)) | D9: =IF(C9="","Baseline required",C9*D$5) -> Baseline required | E9: =IF(C9="","Baseline required",C9*E$5) -> Baseline required | F9: =IF(C9="","Baseline required",C9*F$5) -> Baseline required
A10: Oxygen stewardship | B10: Annual oxygen spend | C10: =IF(Inputs!$C$18="","",Inputs!$C$18) | D10: =IF(C10="","Baseline required",C10*D$5) -> Baseline required | E10: =IF(C10="","Baseline required",C10*E$5) -> Baseline required | F10: =IF(C10="","Baseline required",C10*F$5) -> Baseline required
A11: Consumable standardization | B11: Annual respiratory consumable spend | C11: =IF(Inputs!$C$19="","",Inputs!$C$19) | D11: =IF(C11="","Baseline required",C11*D$5) -> Baseline required | E11: =IF(C11="","Baseline required",C11*E$5) -> Baseline required | F11: =IF(C11="","Baseline required",C11*F$5) -> Baseline required
A12: Equipment utilization | B12: Rental + maintenance + planned purchases | C12: =IF(COUNT(Inputs!$C$20,Inputs!$C$21,Inputs!$C$22)=0,"",SUM(Inputs!$C$20,Inputs!$C$21,Inputs!$C$22)) | D12: =IF(C12="","Baseline required",C12*D$5) -> Baseline required | E12: =IF(C12="","Baseline required",C12*E$5) -> Baseline required | F12: =IF(C12="","Baseline required",C12*F$5) -> Baseline required
A13: Staffing & outsourcing | B13: Overtime + PFT outsourcing + external respiratory services | C13: =IF(COUNT(Inputs!$C$24,Inputs!$C$25,Inputs!$C$26)=0,"",SUM(Inputs!$C$24,Inputs!$C$25,Inputs!$C$26)) | D13: =IF(C13="","Baseline required",C13*D$5) -> Baseline required | E13: =IF(C13="","Baseline required",C13*E$5) -> Baseline required | F13: =IF(C13="","Baseline required",C13*F$5) -> Baseline required
A14: Total cost-avoidance opportunity | B14: Sum of levers with data (check overlaps — see Read Me, Rule 4) | C14: =IF(COUNT(C8:C13)=0,"Baseline required",SUM(C8:C13)) -> Baseline required | D14: =IF(COUNT(D8:D13)=0,"Baseline required",SUM(D8:D13)) -> Baseline required | E14: =IF(COUNT(E8:E13)=0,"Baseline required",SUM(E8:E13)) -> Baseline required | F14: =IF(COUNT(F8:F13)=0,"Baseline required",SUM(F8:F13)) -> Baseline required
A16: Levers reported as 'Baseline required' are excluded from totals.

Sheet Revenue
A1: Revenue creation (gross potential, EGP)
A2: ICU Respiratory Management Package = commercial assumption, subject to Elite Finance, payer and contract validation. Gross potential revenue — not profit.
A4: ICU beds | B4: =Inputs!$C$6 -> 50
A5: Days per month | B5: 30 | C5: Assumption: 30-day month
A6: Days per year | B6: 365 | C6: Assumption: 365-day year
A8: Package price per occupied ICU respiratory patient-day (EGP)
B9: Price scenarios → | C9: 800 | D9: 1000 | E9: 1200
A10: Occupancy scenarios
A11: 0.6
A12: 0.7
A13: 0.8
A14: 0.9
A16: Daily gross potential (EGP / day)
A17: Occupancy | B17: Occupied beds | C17: =C$9 -> 800 | D17: =D$9 -> 1000 | E17: =E$9 -> 1200
A18: =$A$11 -> 0.6 | B18: =$B$4*A18 -> 30 | C18: =$B18*C$9 -> 24000 | D18: =$B18*D$9 -> 30000 | E18: =$B18*E$9 -> 36000
A19: =$A$12 -> 0.7 | B19: =$B$4*A19 -> 35 | C19: =$B19*C$9 -> 28000 | D19: =$B19*D$9 -> 35000 | E19: =$B19*E$9 -> 42000
A20: =$A$13 -> 0.8 | B20: =$B$4*A20 -> 40 | C20: =$B20*C$9 -> 32000 | D20: =$B20*D$9 -> 40000 | E20: =$B20*E$9 -> 48000
A21: =$A$14 -> 0.9 | B21: =$B$4*A21 -> 45 | C21: =$B21*C$9 -> 36000 | D21: =$B21*D$9 -> 45000 | E21: =$B21*E$9 -> 54000
A23: Monthly gross potential (EGP / month)
A24: Occupancy | B24: Occupied beds | C24: =C$9 -> 800 | D24: =D$9 -> 1000 | E24: =E$9 -> 1200
A25: =$A$11 -> 0.6 | B25: =$B$4*A25 -> 30 | C25: =$B25*C$9*$B$5 -> 720000 | D25: =$B25*D$9*$B$5 -> 900000 | E25: =$B25*E$9*$B$5 -> 1080000
A26: =$A$12 -> 0.7 | B26: =$B$4*A26 -> 35 | C26: =$B26*C$9*$B$5 -> 840000 | D26: =$B26*D$9*$B$5 -> 1050000 | E26: =$B26*E$9*$B$5 -> 1260000
A27: =$A$13 -> 0.8 | B27: =$B$4*A27 -> 40 | C27: =$B27*C$9*$B$5 -> 960000 | D27: =$B27*D$9*$B$5 -> 1200000 | E27: =$B27*E$9*$B$5 -> 1440000
A28: =$A$14 -> 0.9 | B28: =$B$4*A28 -> 45 | C28: =$B28*C$9*$B$5 -> 1080000 | D28: =$B28*D$9*$B$5 -> 1350000 | E28: =$B28*E$9*$B$5 -> 1620000
A30: Annual gross potential (EGP / year)
A31: Occupancy | B31: Occupied beds | C31: =C$9 -> 800 | D31: =D$9 -> 1000 | E31: =E$9 -> 1200
A32: =$A$11 -> 0.6 | B32: =$B$4*A32 -> 30 | C32: =$B32*C$9*$B$6 -> 8760000 | D32: =$B32*D$9*$B$6 -> 10950000 | E32: =$B32*E$9*$B$6 -> 13140000
A33: =$A$12 -> 0.7 | B33: =$B$4*A33 -> 35 | C33: =$B33*C$9*$B$6 -> 10220000 | D33: =$B33*D$9*$B$6 -> 12775000 | E33: =$B33*E$9*$B$6 -> 15330000
A34: =$A$13 -> 0.8 | B34: =$B$4*A34 -> 40 | C34: =$B34*C$9*$B$6 -> 11680000 | D34: =$B34*D$9*$B$6 -> 14600000 | E34: =$B34*E$9*$B$6 -> 17520000
A35: =$A$14 -> 0.9 | B35: =$B$4*A35 -> 45 | C35: =$B35*C$9*$B$6 -> 13140000 | D35: =$B35*D$9*$B$6 -> 16425000 | E35: =$B35*E$9*$B$6 -> 19710000
A37: Other revenue streams (Elite inputs — leave blank until priced)
A38: Stream | B38: Volume / yr | C38: Price (EGP) | D38: Gross / yr (EGP) | E38: Formula
A39: Pulmonary Function Testing | D39: =IF(OR(B39="",C39=""),"Scenario pending",B39*C39) -> Scenario pending | E39: Tests a year × Elite PFT tariff
A40: Education Center | D40: =IF(OR(B40="",C40=""),"Scenario pending",B40*C40) -> Scenario pending | E40: Participants × course fee
A41: Future clinical programs | D41: =IF(OR(B41="",C41=""),"Scenario pending",B41*C41) -> Scenario pending | E41: Enrolled patients × program fee
A43: Contribution margin — ICU package (selected scenario on 'Value Bridge')
A44: Gross ICU package revenue (selected scenario) | B44: ='Value Bridge'!C10 -> 14600000
A45: RT salaries
A46: Supervisor / lead salaries
A47: Clinical education
...

Sheet Value Bridge
A1: Hospital financial value bridge (EGP / year)
A2: Gross revenue − RT operating cost + cost avoided = net respiratory service-line value. Steps without Elite data are excluded and flagged.
A4: Selected occupancy | C4: 0.8 | D4: Use the dropdowns (blue). Elite actual occupancy can replace this once known.
A5: Selected package price (EGP / patient-day) | C5: 1000
A6: Selected savings scenario | C6: Mid
A8: Bridge step | B8: Type | C8: EGP / year | D8: Status
A10: ICU package revenue (gross) | B10: Revenue | C10: =Revenue!$B$4*$C$4*$C$5*Revenue!$B$6 -> 14600000 | D10: =IF(ISNUMBER(C10),"Calculated","Not yet quantified — excluded") -> Calculated
A11: PFT revenue | B11: Revenue | C11: =Revenue!D39 -> Scenario pending | D11: =IF(ISNUMBER(C11),"Calculated","Not yet quantified — excluded") -> Not yet quantified — excluded
A12: Education revenue | B12: Revenue | C12: =Revenue!D40 -> Scenario pending | D12: =IF(ISNUMBER(C12),"Calculated","Not yet quantified — excluded") -> Not yet quantified — excluded
A13: Future clinical programs | B13: Revenue | C13: =Revenue!D41 -> Scenario pending | D13: =IF(ISNUMBER(C13),"Calculated","Not yet quantified — excluded") -> Not yet quantified — excluded
A14: Billing leakage recovery | B14: Revenue | C14: =IF(OR(Inputs!$C$37="",Inputs!$C$38="",Inputs!$C$39=""),"Baseline required",Inputs!$C$37*Inputs!$C$38*Inputs!$C$39) -> Baseline required | D14: =IF(ISNUMBER(C14),"Calculated","Not yet quantified — excluded") -> Not yet quantified — excluded
A15: RT service operating cost | B15: Cost | C15: =IF(ISNUMBER(Revenue!$B$55),-Revenue!$B$55,"Elite data required") -> Elite data required | D15: =IF(ISNUMBER(C15),"Calculated","Not yet quantified — excluded") -> Not yet quantified — excluded
A16: Ventilator resources | B16: Cost avoidance | C16: =INDEX('Savings Scenarios'!$D$8:$F$8,MATCH($C$6,'Savings Scenarios'!$D$4:$F$4,0)) -> Baseline required | D16: =IF(ISNUMBER(C16),"Calculated","Not yet quantified — excluded") -> Not yet quantified — excluded
A17: NIV / HFNC utilization | B17: Cost avoidance | C17: =INDEX('Savings Scenarios'!$D$9:$F$9,MATCH($C$6,'Savings Scenarios'!$D$4:$F$4,0)) -> Baseline required | D17: =IF(ISNUMBER(C17),"Calculated","Not yet quantified — excluded") -> Not yet quantified — excluded
A18: Oxygen stewardship | B18: Cost avoidance | C18: =INDEX('Savings Scenarios'!$D$10:$F$10,MATCH($C$6,'Savings Scenarios'!$D$4:$F$4,0)) -> Baseline required | D18: =IF(ISNUMBER(C18),"Calculated","Not yet quantified — excluded") -> Not yet quantified — excluded
A19: Consumable standardization | B19: Cost avoidance | C19: =INDEX('Savings Scenarios'!$D$11:$F$11,MATCH($C$6,'Savings Scenarios'!$D$4:$F$4,0)) -> Baseline required | D19: =IF(ISNUMBER(C19),"Calculated","Not yet quantified — excluded") -> Not yet quantified — excluded
A20: Equipment utilization | B20: Cost avoidance | C20: =INDEX('Savings Scenarios'!$D$12:$F$12,MATCH($C$6,'Savings Scenarios'!$D$4:$F$4,0)) -> Baseline required | D20: =IF(ISNUMBER(C20),"Calculated","Not yet quantified — excluded") -> Not yet quantified — excluded
A21: Staffing & outsourcing | B21: Cost avoidance | C21: =INDEX('Savings Scenarios'!$D$13:$F$13,MATCH($C$6,'Savings Scenarios'!$D$4:$F$4,0)) -> Baseline required | D21: =IF(ISNUMBER(C21),"Calculated","Not yet quantified — excluded") -> Not yet quantified — excluded
A23: Gross revenue (calculated streams) | C23: =SUMIF(B10:B21,"Revenue",C10:C21) -> 14600000
A24: Cost avoidance (calculated levers) | C24: =SUMIF(B10:B21,"Cost avoidance",C10:C21) -> 0
A25: RT operating cost | C25: =SUMIF(B10:B21,"Cost",C10:C21) -> 0
A26: Net respiratory service-line value | C26: =IF(COUNT(C15)=0,"To be quantified",SUM(C23:C25)) -> To be quantified | D26: Shows a value only once RT operating cost is entered — gross revenue alone is not value.
A28: Check: ICU package revenue at 80% occupancy and EGP 1,000 should equal Revenue!D34 (EGP 14,600,000).
